Workbook

Sheet customers
A1: CustomerID | B1: Region | C1: CustomerJoinDate
A2: 345e77bf-4a44-4a4c-9b4f-6f5e21e39e8b | B2: East | C2: 45141
A3: c672d9cb-b74b-48ea-bff3-908ff9790632 | B3: West | C3: 44998
A4: 19ebe822-7b55-4146-9fbf-7f30a95fcc27 | B4: West | C4: 45177
A5: 8553b15d-bab5-41e2-b9b1-3bd3e2a7c51e | B5: West | C5: 45033
A6: 2de84462-b349-47ab-8700-7ac254586db9 | B6: West | C6: 44949
A7: cc8645a3-a19b-4915-9cc6-2dce14049120 | B7: West | C7: 45195
A8: 96550947-3cf0-4e17-816e-b347b9a4b83a | B8: East | C8: 45072
A9: 515d5080-8725-4a15-b600-a0b1c9761f39 | B9: West | C9: 45106
A10: 23781516-59fe-4b3b-af71-4d6cb8a012ad | B10: East | C10: 45214
A11: 977445c9-8561-4c71-a03c-ddf327b5dfc2 | B11: West | C11: 45134
A12: ebd558e7-7e80-4319-b5f2-1bbd43d443b7 | B12: East | C12: 45050
A13: 0a5d8031-b5a7-4be4-8d5d-63b70f2a67c7 | B13: East | C13: 45182
... A195: be63b537-602b-468d-8f5b-44bec4d517db | B195: North | C195: 44947

Sheet Products
A1: ProductID | B1: ProductName | C1: ProductCategory | D1: Price | E1: Base_Cost
A2: 1001 | B2: Single-Origin Ethiopian (250g) | C2: Consumables | D2: 19.49 | E2: 11.55
A3: 1002 | B3: Seasonal Blend Light Roast | C3: Consumables | D3: 35.53 | E3: 5.39
A4: 1003 | B4: Decaf Blend (1kg) | C4: Consumables | D4: 40.35 | E4: 11.69
A5: 1004 | B5: Cold Brew Concentrate | C5: Consumables | D5: 23.49 | E5: 9.17
A6: 1005 | B6: Espresso Bean Sampler Pack | C6: Consumables | D6: 19.06 | E6: 10.88
A7: 1006 | B7: Precision Electric Grinder | C7: Grinders & Brewers | D7: 232.2 | E7: 71.26
A8: 1007 | B8: Hand Grinder (Travel Size) | C8: Grinders & Brewers | D8: 254.72 | E8: 118.44
A9: 1008 | B9: Automated Drip Brewer | C9: Grinders & Brewers | D9: 235.76 | E9: 120.44
A10: 1009 | B10: High-Capacity French Press | C10: Grinders & Brewers | D10: 338.36 | E10: 134.7
A11: 1010 | B11: Pour-Over Starter Kit | C11: Grinders & Brewers | D11: 105.23 | E11: 67.95
A12: 1011 | B12: Digital Coffee Scale | C12: Accessories | D12: 26.83 | E12: 13.32
A13: 1012 | B13: Gooseneck Electric Kettle | C13: Accessories | D13: 34.87 | E13: 23.61
... A51: 1050 | B51: Subscription Renewal Service | C51: Subscriptions | D51: 73.41 | E51: 24.81

Sheet Sheet29
A3: ProductName | B3: Sum of Revenue
A4: Airtight Storage Container | B4: 7019.6
A5: Automated Drip Brewer | B5: 28526.96
A6: Bi-Weekly Sampler Box | B6: 13493.04
A7: Branded Ceramic Mug (Large) | B7: 4449.6
A8: Chemex Filters (100 pack) | B8: 2964.3
A9: Cold Brew Concentrate | B9: 2278.53
A10: Daily Grind T-Shirt | B10: 2179.74
A11: Decaf Blend (1kg) | B11: 5003.4
A12: Digital Coffee Scale | B12: 2790.32
A13: Espresso Bean Sampler Pack | B13: 1829.76
A14: Espresso Lovers Quarterly Pack | B14: 8160.83
A15: Gooseneck Electric Kettle | B15: 4149.53
... A29: Grand Total | B29: 235738.29
A34: Product category | B34: Sum of Revenue
A35: Accessories | B35: 19650.44
A36: Grinders & Brewers | B36: 135760.65
A37: Subscriptions | B37: 47108.27
A38: Merchandise | B38: 17717.84
A39: Consumables | B39: 15501.09
A40: Grand Total | B40: 235738.29
A43: Region | B43: Sum of Profit
A44: East | B44: 36608.7
A45: South | B45: 17529.92
A46: West | B46: 53506.48
A47: North | B47: 15947.07
A48: Grand Total | B48: 123592.17

Sheet Orders
A1: OrderID | B1: CustomerID | C1: Product category | D1: ProductName | E1: Region | F1: ProductID | G1: CustomerJoinDate | H1: OrderDate | I1: Quantity | J1: Revenue | K1: COGS | L1: UnitPrice | M1: Profit
A2: 3685c29f-0492-450c-9a61-e93c633ba866 | B2: a1d952b9-ce77-46c9-a08b-f5e62486096f | C2: =_xlfn.XLOOKUP(F2,Products!$A$2:$A$51,Products!$C$2:$C$51,0) -> Accessories | D2: =_xlfn.XLOOKUP(F2,Products!$A$2:$A$51,Products!$B$2:$B$51,0) -> Airtight Storage Container | E2: =_xlfn.XLOOKUP(B2,customers!$A$2:$A$195,customers!$B$2:$B$195,,0) -> East | F2: 1013 | G2: =_xlfn.XLOOKUP(B2,customers!$A$1:$A$195,customers!$C$1:$C$195) -> 45046 | H2: 45658 | I2: 2 | J2: 122.08 | K2: 51.41 | L2: =_xlfn.XLOOKUP(F2,Products!$A$2:$A$51,Products!$D$2:$D$51,0) -> 61.04 | M2: =J2-K2 -> 70.67
A3: f3c573df-56ce-4619-bc05-7c426de7f2ee | B3: cd62b435-4559-412b-9fab-4861a5e87475 | C3: =_xlfn.XLOOKUP(F3,Products!$A$2:$A$51,Products!$C$2:$C$51,0) -> Grinders & Brewers | D3: =_xlfn.XLOOKUP(F3,Products!$A$2:$A$51,Products!$B$2:$B$51,0) -> High-Capacity French Press | E3: =_xlfn.XLOOKUP(B3,customers!$A$2:$A$195,customers!$B$2:$B$195,,0) -> South | F3: 1034 | G3: =_xlfn.XLOOKUP(B3,customers!$A$1:$A$195,customers!$C$1:$C$195) -> 45174 | H3: 45658 | I3: 1 | J3: 338.36 | K3: 148.17 | L3: =_xlfn.XLOOKUP(F3,Products!$A$2:$A$51,Products!$D$2:$D$51,0) -> 338.36 | M3: =J3-K3 -> 190.19
A4: 59abfb23-1d32-4c33-a5b6-cddb1a61780f | B4: 4566cff3-db65-43ab-ad22-32107433a602 | C4: =_xlfn.XLOOKUP(F4,Products!$A$2:$A$51,Products!$C$2:$C$51,0) -> Subscriptions | D4: =_xlfn.XLOOKUP(F4,Products!$A$2:$A$51,Products!$B$2:$B$51,0) -> Subscription Renewal Service | E4: =_xlfn.XLOOKUP(B4,customers!$A$2:$A$195,customers!$B$2:$B$195,,0) -> East | F4: 1050 | G4: =_xlfn.XLOOKUP(B4,customers!$A$1:$A$195,customers!$C$1:$C$195) -> 45264 | H4: 45658 | I4: 4 | J4: 293.64 | K4: 109.16 | L4: =_xlfn.XLOOKUP(F4,Products!$A$2:$A$51,Products!$D$2:$D$51,0) -> 73.41 | M4: =J4-K4 -> 184.48
A5: f85ca148-9dcc-4488-a3ce-48bb5fdb0ad6 | B5: 7f9f3881-a8b6-4a15-a3fb-4f4b7e75e1ef | C5: =_xlfn.XLOOKUP(F5,Products!$A$2:$A$51,Products!$C$2:$C$51,0) -> Subscriptions | D5: =_xlfn.XLOOKUP(F5,Products!$A$2:$A$51,Products!$B$2:$B$51,0) -> Monthly Dark Roast Subscription | E5: =_xlfn.XLOOKUP(B5,customers!$A$2:$A$195,customers!$B$2:$B$195,,0) -> South | F5: 1021 | G5: =_xlfn.XLOOKUP(B5,customers!$A$1:$A$195,customers!$C$1:$C$195) -> 45079 | H5: 45658 | I5: 3 | J5: 183.78 | K5: 105.44 | L5: =_xlfn.XLOOKUP(F5,Products!$A$2:$A$51,Products!$D$2:$D$51,0) -> 61.26 | M5: =J5-K5 -> 78.34
A6: f333a8e1-66ba-46f3-a830-a154afc0e56a | B6: 596febf3-9aa4-4c07-88ab-f7662388e50c | C6: =_xlfn.XLOOKUP(F6,Products!$A$2:$A$51,Products!$C$2:$C$51,0) -> Subscriptions | D6: =_xlfn.XLOOKUP(F6,Products!$A$2:$A$51,Products!$B$2:$B$51,0) -> Espresso Lovers Quarterly Pack | E6: =_xlfn.XLOOKUP(B6,customers!$A$2:$A$195,customers!$B$2:$B$195,,0) -> West | F6: 1024 | G6: =_xlfn.XLOOKUP(B6,customers!$A$1:$A$195,customers!$C$1:$C$195) -> 45193 | H6: 45658 | I6: 3 | J6: 224.61 | K6: 57.58 | L6: =_xlfn.XLOOKUP(F6,Products!$A$2:$A$51,Products!$D$2:$D$51,0) -> 74.87 | M6: =J6-K6 -> 167.03
A7: fb30b1dc-81f6-4030-9dee-516e42a134f6 | B7: c672d9cb-b74b-48ea-bff3-908ff9790632 | C7: =_xlfn.XLOOKUP(F7,Products!$A$2:$A$51,Products!$C$2:$C$51,0) -> Subscriptions | D7: =_xlfn.XLOOKUP(F7,Products!$A$2:$A$51,Products!$B$2:$B$51,0) -> Monthly Dark Roast Subscription | E7: =_xlfn.XLOOKUP(B7,customers!$A$2:$A$195,customers!$B$2:$B$195,,0) -> West | F7: 1046 | G7: =_xlfn.XLOOKUP(B7,customers!$A$1:$A$195,customers!$C$1:$C$195) -> 44998 | H7: 45689 | I7: 1 | J7: 61.26 | K7: 35.15 | L7: =_xlfn.XLOOKUP(F7,Products!$A$2:$A$51,Products!$D$2:$D$51,0) -> 61.26 | M7: =J7-K7 -> 26.11
A8: 715973e8-381f-47ea-9ec0-9ef9a08920ff | B8: dc375298-2549-4d89-b752-d6e8f0a711af | C8: =_xlfn.XLOOKUP(F8,Products!$A$2:$A$51,Products!$C$2:$C$51,0) -> Accessories | D8: =_xlfn.XLOOKUP(F8,Products!$A$2:$A$51,Products!$B$2:$B$51,0) -> Gooseneck Electric Kettle | E8: =_xlfn.XLOOKUP(B8,customers!$A$2:$A$195,customers!$B$2:$B$195,,0) -> North | F8: 1012 | G8: =_xlfn.XLOOKUP(B8,customers!$A$1:$A$195,customers!$C$1:$C$195) -> 45227 | H8: 45689 | I8: 3 | J8: 104.61 | K8: 77.91 | L8: =_xlfn.XLOOKUP(F8,Products!$A$2:$A$51,Products!$D$2:$D$51,0) -> 34.87 | M8: =J8-K8 -> 26.7
A9: fcc2f521-d51e-4965-b29d-f772744667c7 | B9: 8ee81a10-51c3-4f56-82b0-d43244ecdac5 | C9: =_xlfn.XLOOKUP(F9,Products!$A$2:$A$51,Products!$C$2:$C$51,0) -> Subscriptions | D9: =_xlfn.XLOOKUP(F9,Products!$A$2:$A$51,Products!$B$2:$B$51,0) -> Espresso Lovers Quarterly Pack | E9: =_xlfn.XLOOKUP(B9,customers!$A$2:$A$195,customers!$B$2:$B$195,,0) -> East | F9: 1024 | G9: =_xlfn.XLOOKUP(B9,customers!$A$1:$A$195,customers!$C$1:$C$195) -> 45015 | H9: 45689 | I9: 4 | J9: 299.48 | K9: 76.78 | L9: =_xlfn.XLOOKUP(F9,Products!$A$2:$A$51,Products!$D$2:$D$51,0) -> 74.87 | M9: =J9-K9 -> 222.7
A10: f3ab4a96-1727-4306-8d6b-98200dd31748 | B10: 6eb9203d-35ae-4742-bb1e-911b16965477 | C10: =_xlfn.XLOOKUP(F10,Products!$A$2:$A$51,Products!$C$2:$C$51,0) -> Grinders & Brewers | D10: =_xlfn.XLOOKUP(F10,Products!$A$2:$A$51,Products!$B$2:$B$51,0) -> Hand Grinder (Travel Size) | E10: =_xlfn.XLOOKUP(B10,customers!$A$2:$A$195,customers!$B$2:$B$195,,0) -> East | F10: 1032 | G10: =_xlfn.XLOOKUP(B10,customers!$A$1:$A$195,customers!$C$1:$C$195) -> 45251 | H10: 45689 | I10: 1 | J10: 254.72 | K10: 130.28 | L10: =_xlfn.XLOOKUP(F10,Products!$A$2:$A$51,Products!$D$2:$D$51,0) -> 254.72 | M10: =J10-K10 -> 124.44
A11: f67fb8e7-373e-46aa-b512-84abfe710d15 | B11: bf0d6160-338f-4cad-8123-0b5a6763b192 | C11: =_xlfn.XLOOKUP(F11,Products!$A$2:$A$51,Products!$C$2:$C$51,0) -> Grinders & Brewers | D11: =_xlfn.XLOOKUP(F11,Products!$A$2:$A$51,Products!$B$2:$B$51,0) -> Automated Drip Brewer | E11: =_xlfn.XLOOKUP(B11,customers!$A$2:$A$195,customers!$B$2:$B$195,,0) -> South | F11: 1033 | G11: =_xlfn.XLOOKUP(B11,customers!$A$1:$A$195,customers!$C$1:$C$195) -> 45026 | H11: 45717 | I11: 1 | J11: 235.76 | K11: 132.48 | L11: =_xlfn.XLOOKUP(F11,Products!$A$2:$A$51,Products!$D$2:$D$51,0) -> 235.76 | M11: =J11-K11 -> 103.28
A12: a16ee5e4-1df2-4760-8105-7a29fcc11299 | B12: ac0e0eee-04eb-4dd6-bb52-3a2a532b62c0 | C12: =_xlfn.XLOOKUP(F12,Products!$A$2:$A$51,Products!$C$2:$C$51,0) -> Subscriptions | D12: =_xlfn.XLOOKUP(F12,Products!$A$2:$A$51,Products!$B$2:$B$51,0) -> Monthly Dark Roast Subscription | E12: =_xlfn.XLOOKUP(B12,customers!$A$2:$A$195,customers!$B$2:$B$195,,0) -> East | F12: 1021 | G12: =_xlfn.XLOOKUP(B12,customers!$A$1:$A$195,customers!$C$1:$C$195) -> 45239 | H12: 45717 | I12: 1 | J12: 61.26 | K12: 35.15 | L12: =_xlfn.XLOOKUP(F12,Products!$A$2:$A$51,Products!$D$2:$D$51,0) -> 61.26 | M12: =J12-K12 -> 26.11
A13: 1477709f-5755-4892-9a77-fdb2550c0f4f | B13: 515d5080-8725-4a15-b600-a0b1c9761f39 | C13: =_xlfn.XLOOKUP(F13,Products!$A$2:$A$51,Products!$C$2:$C$51,0) -> Merchandise | D13: =_xlfn.XLOOKUP(F13,Products!$A$2:$A$51,Products!$B$2:$B$51,0) -> Daily Grind T-Shirt | E13: =_xlfn.XLOOKUP(B13,customers!$A$2:$A$195,customers!$B$2:$B$195,,0) -> West | F13: 1044 | G13: =_xlfn.XLOOKUP(B13,customers!$A$1:$A$195,customers!$C$1:$C$195) -> 45106 | H13: 45748 | I13: 3 | J13: 64.11 | K13: 24.78 | L13: =_xlfn.XLOOKUP(F13,Products!$A$2:$A$51,Products!$D$2:$D$51,0) -> 21.37 | M13: =J13-K13 -> 39.33
... A35: 505f0b97-f22c-43ab-9a00-a3622efca95f | B35: ee0a4bac-514b-47e0-afb3-0643ed31e7c0 | C35: =_xlfn.XLOOKUP(F35,Products!$A$2:$A$51,Products!$C$2:$C$51,0) -> Subscriptions | D35: =_xlfn.XLOOKUP(F35,Products!$A$2:$A$51,Products!$B$2:$B$51,0) -> Espresso Lovers Quarterly Pack | E35: =_xlfn.XLOOKUP(B35,customers!$A$2:$A$195,customers!$B$2:$B$195,,0) -> East | F35: 1049 | G35: =_xlfn.XLOOKUP(B35,customers!$A$1:$A$195,customers!$C$1:$C$195) -> 45115 | H35: 45931 | I35: 3 | J35: 224.61 | K35: 57.58 | L35: =_xlfn.XLOOKUP(F35,Products!$A$2:$A$51,Products!$D$2:$D$51,0) -> 74.87 | M35: =J35-K35 -> 167.03
A36: a7ccc132-c9f1-4b54-bd29-9f81fb23b5e3 | B36: bbccecfa-0eaa-433d-81c9-1fddba3792d4 | C36: =_xlfn.XLOOKUP(F36,Products!$A$2:$A$51,Products!$C$2:$C$51,0) -> Accessories | D36: =_xlfn.XLOOKUP(F36,Products!$A$2:$A$51,Products!$B$2:$B$51,0) -> Digital Coffee Scale | E36: =_xlfn.XLOOKUP(B36,customers!$A$2:$A$195,customers!$B$2:$B$195,,0) -> West | F36: 1036 | G36: =_xlfn.XLOOKUP(B36,customers!$A$1:$A$195,customers!$C$1:$C$195) -> 45037 | H36: 1/13/2025 | I36: 3 | J36: 80.49 | K36: 43.96 | L36: =_xlfn.XLOOKUP(F36,Products!$A$2:$A$51,Products!$D$2:$D$51,0) -> 26.83 | M36: =J36-K36 -> 36.53
A37: caf0fb18-72e0-4c11-a3c3-9e7434528f44 | B37: d4b53af0-6d06-4d0e-b2e1-b84de575e1c5 | C37: =_xlfn.XLOOKUP(F37,Products!$A$2:$A$51,Products!$C$2:$C$51,0) -> Consumables | D37: =_xlfn.XLOOKUP(F37,Products!$A$2:$A$51,Products!$B$2:$B$51,0) -> Seasonal Blend Light Roast | E37: =_xlfn.XLOOKUP(B37,customers!$A$2:$A$195,customers!$B$2:$B$195,,0) -> North | F37: 1027 | G37: =_xlfn.XLOOKUP(B37,customers!$A$1:$A$195,customers!$C$1:$C$195) -> 45070 | H37: 1/13/2025 | I37: 1 | J37: 35.53 | K37: 5.93 | L37: =_xlfn.XLOOKUP(F37,Products!$A$2:$A$51,Products!$D$2:$D$51,0) -> 35.53 | M37: =J37-K37 -> 29.6
A38: a521ec8a-381d-4739-a765-3ed244b3e9a7 | B38: 46ee2157-1365-44f4-ae66-e5855c3779d7 | C38: =_xlfn.XLOOKUP(F38,Products!$A$2:$A$51,Products!$C$2:$C$51,0) -> Merchandise | D38: =_xlfn.XLOOKUP(F38,Products!$A$2:$A$51,Products!$B$2:$B$51,0) -> Daily Grind T-Shirt | E38: =_xlfn.XLOOKUP(B38,customers!$A$2:$A$195,customers!$B$2:$B$195,,0) -> East | F38: 1044 | G38: =_xlfn.XLOOKUP(B38,customers!$A$1:$A$195,customers!$C$1:$C$195) -> 45262 | H38: 1/13/2025 | I38: 4 | J38: 85.48 | K38: 33.04 | L38: =_xlfn.XLOOKUP(F38,Products!$A$2:$A$51,Products!$D$2:$D$51,0) -> 21.37 | M38: =J38-K38 -> 52.44
A39: b850d516-7c7f-467c-9727-cbefdc6dc599 | B39: e9525326-8155-4e1c-8bad-6dbc399bf3d5 | C39: =_xlfn.XLOOKUP(F39,Products!$A$2:$A$51,Products!$C$2:$C$51,0) -> Consumables | D39: =_xlfn.XLOOKUP(F39,Products!$A$2:$A$51,Products!$B$2:$B$51,0) -> Decaf Blend (1kg) | E39: =_xlfn.XLOOKUP(B39,customers!$A$2:$A$195,customers!$B$2:$B$195,,0) -> West | F39: 1028 | G39: =_xlfn.XLOOKUP(B39,customers!$A$1:$A$195,customers!$C$1:$C$195) -> 45084 | H39: 1/13/2025 | I39: 4 | J39: 161.4 | K39: 51.44 | L39: =_xlfn.XLOOKUP(F39,Products!$A$2:$A$51,Products!$D$2:$D$51,0) -> 40.35 | M39: =J39-K39 -> 109.96
A40: c2ccc14b-7a3a-4d1e-8f41-ad5d4f96b4b8 | B40: 80ff4978-481e-4e21-a861-b4000fe3f313 | C40: =_xlfn.XLOOKUP(F40,Products!$A$2:$A$51,Products!$C$2:$C$51,0) -> Merchandise | D40: =_xlfn.XLOOKUP(F40,Products!$A$2:$A$51,Products!$B$2:$B$51,0) -> Logo Hoodie (Black) | E40: =_xlfn.XLOOKUP(B40,customers!$A$2:$A$195,customers!$B$2:$B$195,,0) -> East | F40: 1042 | G40: =_xlfn.XLOOKUP(B40,customers!$A$1:$A$195,customers!$C$1:$C$195) -> 45276 | H40: 1/14/2025 | I40: 4 | J40: 60.92 | K40: 53.59 | L40: =_xlfn.XLOOKUP(F40,Products!$A$2:$A$51,Products!$D$2:$D$51,0) -> 15.23 | M40: =J40-K40 -> 7.33
A41: 57db7af4-8ccf-4a99-873f-3e558361c69b | B41: 1959deb4-14ea-44cb-b5a1-915e9485b006 | C41: =_xlfn.XLOOKUP(F41,Products!$A$2:$A$51,Products!$C$2:$C$51,0) -> Grinders & Brewers | D41: =_xlfn.XLOOKUP(F41,Products!$A$2:$A$51,Products!$B$2:$B$51,0) -> Pour-Over Starter Kit | E41: =_xlfn.XLOOKUP(B41,customers!$A$2:$A$195,customers!$B$2:$B$195,,0) -> East | F41: 1035 | G41: =_xlfn.XLOOKUP(B41,customers!$A$1:$A$195,customers!$C$1:$C$195) -> 45074 | H41: 1/14/2025 | I41: 2 | J41: 210.46 | K41: 149.49 | L41: =_xlfn.XLOOKUP(F41,Products!$A$2:$A$51,Products!$D$2:$D$51,0) -> 105.23 | M41: =J41-K41 -> 60.97
A42: 7846b8ec-03de-4bac-96ce-64c03a9940c4 | B42: 25d277dc-e796-4782-a7ef-3e1d2fb59188 | C42: =_xlfn.XLOOKUP(F42,Products!$A$2:$A$51,Products!$C$2:$C$51,0) -> Subscriptions | D42: =_xlfn.XLOOKUP(F42,Products!$A$2:$A$51,Products!$B$2:$B$51,0) -> Espresso Lovers Quarterly Pack | E42: =_xlfn.XLOOKUP(B42,customers!$A$2:$A$195,customers!$B$2:$B$195,,0) -> West | F42: 1049 | G42: =_xlfn.XLOOKUP(B42,customers!$A$1:$A$195,customers!$C$1:$C$195) -> 45041 | H42: 1/14/2025 | I42: 1 | J42: 74.87 | K42: 19.2 | L42: =_xlfn.XLOOKUP(F42,Products!$A$2:$A$51,Products!$D$2:$D$51,0) -> 74.87 | M42: =J42-K42 -> 55.67
A43: 1f1da2b2-469d-4733-a4ce-45a1e094adfc | B43: 18405ad5-5712-4ee4-84fd-9e682ad3d596 | C43: =_xlfn.XLOOKUP(F43,Products!$A$2:$A$51,Products!$C$2:$C$51,0) -> Merchandise | D43: =_xlfn.XLOOKUP(F43,Products!$A$2:$A$51,Products!$B$2:$B$51,0) -> Minimalist Keychain | E43: =_xlfn.XLOOKUP(B43,customers!$A$2:$A$195,customers!$B$2:$B$195,,0) -> West | F43: 1020 | G43: =_xlfn.XLOOKUP(B43,customers!$A$1:$A$195,customers!$C$1:$C$195) -> 45166 | H43: 1/14/2025 | I43: 3 | J43: 82.11 | K43: 72.27 | L43: =_xlfn.XLOOKUP(F43,Products!$A$2:$A$51,Products!$D$2:$D$51,0) -> 27.37 | M43: =J43-K43 -> 9.84
A44: 117d5477-ce3a-4229-807e-deb135b0eb6d | B44: 3027e6f9-f285-49fb-93a7-932583102f1b | C44: =_xlfn.XLOOKUP(F44,Products!$A$2:$A$51,Products!$C$2:$C$51,0) -> Consumables | D44: =_xlfn.XLOOKUP(F44,Products!$A$2:$A$51,Products!$B$2:$B$51,0) -> Cold Brew Concentrate | E44: =_xlfn.XLOOKUP(B44,customers!$A$2:$A$195,customers!$B$2:$B$195,,0) -> East | F44: 1004 | G44: =_xlfn.XLOOKUP(B44,customers!$A$1:$A$195,customers!$C$1:$C$195) -> 45171 | H44: 1/15/2025 | I44: 4 | J44: 93.96 | K44: 40.35 | L44: =_xlfn.XLOOKUP(F44,Products!$A$2:$A$51,Products!$D$2:$D$51,0) -> 23.49 | M44: =J44-K44 -> 53.61
A45: ecf82f5d-fd6f-4458-9a8a-afe77914b9b3 | B45: 3aea3b26-9c7a-481d-890c-b9ebb40358e0 | C45: =_xlfn.XLOOKUP(F45,Products!$A$2:$A$51,Products!$C$2:$C$51,0) -> Merchandise | D45: =_xlfn.XLOOKUP(F45,Products!$A$2:$A$51,Products!$B$2:$B$51,0) -> Minimalist Keychain | E45: =_xlfn.XLOOKUP(B45,customers!$A$2:$A$195,customers!$B$2:$B$195,,0) -> North | F45: 1045 | G45: =_xlfn.XLOOKUP(B45,customers!$A$1:$A$195,customers!$C$1:$C$195) -> 45039 | H45: 1/15/2025 | I45: 3 | J45: 82.11 | K45: 72.27 | L45: =_xlfn.XLOOKUP(F45,Products!$A$2:$A$51,Products!$D$2:$D$51,0) -> 27.37 | M45: =J45-K45 -> 9.84
A46: 864c811c-b827-4e0f-8420-bc615a96c99d | B46: d4b53af0-6d06-4d0e-b2e1-b84de575e1c5 | C46: =_xlfn.XLOOKUP(F46,Products!$A$2:$A$51,Products!$C$2:$C$51,0) -> Subscriptions | D46: =_xlfn.XLOOKUP(F46,Products!$A$2:$A$51,Products!$B$2:$B$51,0) -> Subscription Renewal Service | E46: =_xlfn.XLOOKUP(B46,customers!$A$2:$A$195,customers!$B$2:$B$195,,0) -> North | F46: 1050 | G46: =_xlfn.XLOOKUP(B46,customers!$A$1:$A$195,customers!$C$1:$C$195) -> 45070 | H46: 1/16/2025 | I46: 3 | J46: 220.23 | K46: 81.87 | L46: =_xlfn.XLOOKUP(F46,Products!$A$2:$A$51,Products!$D$2:$D$51,0) -> 73.41 | M46: =J46-K46 -> 138.36
A47: fbe8fb57-1729-479e-95c7-825a953dca20 | B47: d84a5bc4-af44-4030-9e24-d893b6f6e966 | C47: =_xlfn.XLOOKUP(F47,Products!$A$2:$A$51,Products!$C$2:$C$51,0) -> Consumables | D47: =_xlfn.XLOOKUP(F47,Products!$A$2:$A$51,Products!$B$2:$B$51,0) -> Single-Origin Ethiopian (250g) | E47: =_xlfn.XLOOKUP(B47,customers!$A$2:$A$195,customers!$B$2:$B$195,,0) -> East | F47: 1001 | G47: =_xlfn.XLOOKUP(B47,customers!$A$1:$A$195,customers!$C$1:$C$195) -> 45272 | H47: 1/17/2025 | I47: 1 | J47: 19.49 | K47: 12.71 | L47: =_xlfn.XLOOKUP(F47,Products!$A$2:$A$51,Products!$D$2:$D$51,0) -> 19.49 | M47: =J47-K47 -> 6.78
... A87: b6871d70-15e2-4b50-ae73-e5d13879d775 | B87: 0e025dda-dcfd-4349-b45d-994ba4664cb3 | C87: =_xlfn.XLOOKUP(F87,Products!$A$2:$A$51,Products!$C$2:$C$51,0) -> Accessories | D87: =_xlfn.XLOOKUP(F87,Products!$A$2:$A$51,Products!$B$2:$B$51,0) -> Airtight Storage Container | E87: =_xlfn.XLOOKUP(B87,customers!$A$2:$A$195,customers!$B$2:$B$195,,0) -> West | F87: 1038 | G87: =_xlfn.XLOOKUP(B87,customers!$A$1:$A$195,customers!$C$1:$C$195) -> 45237 | H87: 1/30/2025 | I87: 4 | J87: 244.16 | K87: 102.83 | L87: =_xlfn.XLOOKUP(F87,Products!$A$2:$A$51,Products!$D$2:$D$51,0) -> 61.04 | M87: =J87-K87 -> 141.33
A88: 6135b1ff-9204-4e49-ad91-2678d7e8c8d1 | B88: b7fd8f42-7477-4c83-ba82-eee3bef2f366 | C88: =_xlfn.XLOOKUP(F88,Products!$A$2:$A$51,Products!$C$2:$C$51,0) -> Grinders & Brewers | D88: =_xlfn.XLOOKUP(F88,Products!$A$2:$A$51,Products!$B$2:$B$51,0) -> Hand Grinder (Travel Size) | E88: =_xlfn.XLOOKUP(B88,customers!$A$2:$A$195,customers!$B$2:$B$195,,0) -> South | F88: 1032 | G88: =_xlfn.XLOOKUP(B88,customers!$A$1:$A$195,customers!$C$1:$C$195) -> 45136 | H88: 45659 | I88: 2 | J88: 509.44 | K88: 260.57 | L88: =_xlfn.XLOOKUP(F88,Products!$A$2:$A$51,Products!$D$2:$D$51,0) -> 254.72 | M88: =J88-K88 -> 248.87
A89: b0107dfd-71ae-4228-ab49-0b38d0dfa016 | B89: 08d68de0-766e-42e3-9145-4e030f805140 | C89: =_xlfn.XLOOKUP(F89,Products!$A$2:$A$51,Products!$C$2:$C$51,0) -> Subscriptions | D89: =_xlfn.XLOOKUP(F89,Products!$A$2:$A$51,Products!$B$2:$B$51,0) -> Monthly Dark Roast Subscription | E89: =_xlfn.XLOOKUP(B89,customers!$A$2:$A$195,customers!$B$2:$B$195,,0) -> East | F89: 1021 | G89: =_xlfn.XLOOKUP(B89,customers!$A$1:$A$195,customers!$C$1:$C$195) -> 45253 | H89: 45690 | I89: 4 | J89: 245.04 | K89: 140.58 | L89: =_xlfn.XLOOKUP(F89,Products!$A$2:$A$51,Products!$D$2:$D$51,0) -> 61.26 | M89: =J89-K89 -> 104.46
A90: 15c6d0c2-ca8e-4d95-a61c-e2bfd438b07e | B90: 345e77bf-4a44-4a4c-9b4f-6f5e21e39e8b | C90: =_xlfn.XLOOKUP(F90,Products!$A$2:$A$51,Products!$C$2:$C$51,0) -> Consumables | D90: =_xlfn.XLOOKUP(F90,Products!$A$2:$A$51,Products!$B$2:$B$51,0) -> Single-Origin Ethiopian (250g) | E90: =_xlfn.XLOOKUP(B90,customers!$A$2:$A$195,customers!$B$2:$B$195,,0) -> East | F90: 1026 | G90: =_xlfn.XLOOKUP(B90,customers!$A$1:$A$195,customers!$C$1:$C$195) -> 45141 | H90: 45718 | I90: 1 | J90: 19.49 | K90: 12.71 | L90: =_xlfn.XLOOKUP(F90,Products!$A$2:$A$51,Products!$D$2:$D$51,0) -> 19.49 | M90: =J90-K90 -> 6.78
A91: 969cea24-b65f-4f57-8159-f3279047b277 | B91: 9db836e7-e5e0-4351-8a5a-37c082766fba | C91: =_xlfn.XLOOKUP(F91,Products!$A$2:$A$51,Products!$C$2:$C$51,0) -> Consumables | D91: =_xlfn.XLOOKUP(F91,Products!$A$2:$A$51,Products!$B$2:$B$51,0) -> Single-Origin Ethiopian (250g) | E91: =_xlfn.XLOOKUP(B91,customers!$A$2:$A$195,customers!$B$2:$B$195,,0) -> East | F91: 1001 | G91: =_xlfn.XLOOKUP(B91,customers!$A$1:$A$195,customers!$C$1:$C$195) -> 45055 | H91: 45718 | I91: 2 | J91: 38.98 | K91: 25.41 | L91: =_xlfn.XLOOKUP(F91,Products!$A$2:$A$51,Products!$D$2:$D$51,0) -> 19.49 | M91: =J91-K91 -> 13.57
A92: 096b3ee9-9aab-4fb5-b77f-da59a44da964 | B92: 39a1dc8b-c9b4-4377-adb6-8eeef78d8192 | C92: =_xlfn.XLOOKUP(F92,Products!$A$2:$A$51,Products!$C$2:$C$51,0) -> Merchandise | D92: =_xlfn.XLOOKUP(F92,Products!$A$2:$A$51,Products!$B$2:$B$51,0) -> Branded Ceramic Mug (Large) | E92: =_xlfn.XLOOKUP(B92,customers!$A$2:$A$195,customers!$B$2:$B$195,,0) -> South | F92: 1041 | G92: =_xlfn.XLOOKUP(B92,customers!$A$1:$A$195,customers!$C$1:$C$195) -> 45204 | H92: 45718 | I92: 1 | J92: 43.2 | K92: 31.11 | L92: =_xlfn.XLOOKUP(F92,Products!$A$2:$A$51,Products!$D$2:$D$51,0) -> 43.2 | M92: =J92-K92 -> 12.09
A93: 5c42f13b-cae6-4bc9-8847-02054b32e90d | B93: 989bc40e-1776-4ea5-892f-d2df497c2608 | C93: =_xlfn.XLOOKUP(F93,Products!$A$2:$A$51,Products!$C$2:$C$51,0) -> Grinders & Brewers | D93: =_xlfn.XLOOKUP(F93,Products!$A$2:$A$51,Products!$B$2:$B$51,0) -> High-Capacity French Press | E93: =_xlfn.XLOOKUP(B93,customers!$A$2:$A$195,customers!$B$2:$B$195,,0) -> North | F93: 1034 | G93: =_xlfn.XLOOKUP(B93,customers!$A$1:$A$195,customers!$C$1:$C$195) -> 45015 | H93: 45718 | I93: 1 | J93: 338.36 | K93: 148.17 | L93: =_xlfn.XLOOKUP(F93,Products!$A$2:$A$51,Products!$D$2:$D$51,0) -> 338.36 | M93: =J93-K93 -> 190.19
A94: bbde17b9-d089-45cf-aa59-4217501aa7fc | B94: d4b53af0-6d06-4d0e-b2e1-b84de575e1c5 | C94: =_xlfn.XLOOKUP(F94,Products!$A$2:$A$51,Products!$C$2:$C$51,0) -> Grinders & Brewers | D94: =_xlfn.XLOOKUP(F94,Products!$A$2:$A$51,Products!$B$2:$B$51,0) -> Precision Electric Grinder | E94: =_xlfn.XLOOKUP(B94,customers!$A$2:$A$195,customers!$B$2:$B$195,,0) -> North | F94: 1031 | G94: =_xlfn.XLOOKUP(B94,customers!$A$1:$A$195,customers!$C$1:$C$195) -> 45070 | H94: 45718 | I94: 1 | J94: 232.2 | K94: 78.39 | L94: =_xlfn.XLOOKUP(F94,Products!$A$2:$A$51,Products!$D$2:$D$51,0) -> 232.2 | M94: =J94-K94 -> 153.81
A95: a629b818-1622-445b-a702-83287074f944 | B95: 2de84462-b349-47ab-8700-7ac254586db9 | C95: =_xlfn.XLOOKUP(F95,Products!$A$2:$A$51,Products!$C$2:$C$51,0) -> Merchandise | D95: =_xlfn.XLOOKUP(F95,Products!$A$2:$A$51,Products!$B$2:$B$51,0) -> Branded Ceramic Mug (Large) | E95: =_xlfn.XLOOKUP(B95,customers!$A$2:$A$195,customers!$B$2:$B$195,,0) -> West | F95: 1016 | G95: =_xlfn.XLOOKUP(B95,customers!$A$1:$A$195,customers!$C$1:$C$195) -> 44949 | H95: 45749 | I95: 4 | J95: 172.8 | K95: 124.43 | L95: =_xlfn.XLOOKUP(F95,Products!$A$2:$A$51,Products!$D$2:$D$51,0) -> 43.2 | M95: =J95-K95 -> 48.37
A96: 688e8939-6612-4b88-b16a-6f5bc17859f5 | B96: e5040015-0c1f-4b62-84e4-6278ebfb2842 | C96: =_xlfn.XLOOKUP(F96,Products!$A$2:$A$51,Products!$C$2:$C$51,0) -> Grinders & Brewers | D96: =_xlfn.XLOOKUP(F96,Products!$A$2:$A$51,Products!$B$2:$B$51,0) -> Automated Drip Brewer | E96: =_xlfn.XLOOKUP(B96,customers!$A$2:$A$195,customers!$B$2:$B$195,,0) -> West | F96: 1008 | G96: =_xlfn.XLOOKUP(B96,customers!$A$1:$A$195,customers!$C$1:$C$195) -> 44982 | H96: 45749 | I96: 2 | J96: 471.52 | K96: 264.97 | L96: =_xlfn.XLOOKUP(F96,Products!$A$2:$A$51,Products!$D$2:$D$51,0) -> 235.76 | M96: =J96-K96 -> 206.55
A97: d19769c4-8d1f-4e01-a02f-abaaea593f36 | B97: 31bd87f8-56a1-4ab6-9a7a-716e19ec8220 | C97: =_xlfn.XLOOKUP(F97,Products!$A$2:$A$51,Products!$C$2:$C$51,0) -> Merchandise | D97: =_xlfn.XLOOKUP(F97,Products!$A$2:$A$51,Products!$B$2:$B$51,0) -> Minimalist Keychain | E97: =_xlfn.XLOOKUP(B97,customers!$A$2:$A$195,customers!$B$2:$B$195,,0) -> East | F97: 1045 | G97: =_xlfn.XLOOKUP(B97,customers!$A$1:$A$195,customers!$C$1:$C$195) -> 45143 | H97: 45749 | I97: 2 | J97: 54.74 | K97: 48.18 | L97: =_xlfn.XLOOKUP(F97,Products!$A$2:$A$51,Products!$D$2:$D$51,0) -> 27.37 | M97: =J97-K97 -> 6.56
A98: 1e32daed-7a1e-4599-9eba-46ac10fb3b29 | B98: d8777a29-8b63-48a6-a4d9-c01a69272eec | C98: =_xlfn.XLOOKUP(F98,Products!$A$2:$A$51,Products!$C$2:$C$51,0) -> Consumables | D98: =_xlfn.XLOOKUP(F98,Products!$A$2:$A$51,Products!$B$2:$B$51,0) -> Decaf Blend (1kg) | E98: =_xlfn.XLOOKUP(B98,customers!$A$2:$A$195,customers!$B$2:$B$195,,0) -> West | F98: 1003 | G98: =_xlfn.XLOOKUP(B98,customers!$A$1:$A$195,customers!$C$1:$C$195) -> 45132 | H98: 45749 | I98: 3 | J98: 121.05 | K98: 38.58 | L98: =_xlfn.XLOOKUP(F98,Products!$A$2:$A$51,Products!$D$2:$D$51,0) -> 40.35 | M98: =J98-K98 -> 82.47
A99: 0cec6677-5993-4be9-92ab-78bc1311280f | B99: c773874c-adcd-4b21-9d8f-f72f3b3cb8eb | C99: =_xlfn.XLOOKUP(F99,Products!$A$2:$A$51,Products!$C$2:$C$51,0) -> Accessories | D99: =_xlfn.XLOOKUP(F99,Products!$A$2:$A$51,Products!$B$2:$B$51,0) -> Chemex Filters (100 pack) | E99: =_xlfn.XLOOKUP(B99,customers!$A$2:$A$195,customers!$B$2:$B$195,,0) -> West | F99: 1014 | G99: =_xlfn.XLOOKUP(B99,customers!$A$1:$A$195,customers!$C$1:$C$195) -> 45216 | H99: 45749 | I99: 4 | J99: 96.4 | K99: 84.83 | L99: =_xlfn.XLOOKUP(F99,Products!$A$2:$A$51,Products!$D$2:$D$51,0) -> 24.1 | M99: =J99-K99 -> 11.57
... A130: c7c55120-961e-4a21-a5cd-0daf2d89d19a | B130: 4c71f46b-aec0-4b76-92c5-beda74b59e13 | C130: =_xlfn.XLOOKUP(F130,Products!$A$2:$A$51,Products!$C$2:$C$51,0) -> Merchandise | D130: =_xlfn.XLOOKUP(F130,Products!$A$2:$A$51,Products!$B$2:$B$51,0) -> Minimalist Keychain | E130: =_xlfn.XLOOKUP(B130,customers!$A$2:$A$195,customers!$B$2:$B$195,,0) -> West | F130: 1045 | G130: =_xlfn.XLOOKUP(B130,customers!$A$1:$A$195,customers!$C$1:$C$195) -> 45282 | H130: 45993 | I130: 1 | J130: 27.37 | K130: 24.09 | L130: =_xlfn.XLOOKUP(F130,Products!$A$2:$A$51,Products!$D$2:$D$51,0) -> 27.37 | M130: =J130-K130 -> 3.28
...

Sheet Pivot Table
A3: CustomerID | B3: Max of OrderDate | C3: Distinct Count of OrderID | D3: Sum of Revenue
A4: 006bc8ad-8e59-4d6f-ab38-475a02a0f952 | B4: 45785 | C4: 8 | D4: 1248.55
A5: 019d6740-e346-47b9-b042-acab3646d400 | B5: 45843 | C5: 10 | D5: 825.56
A6: 01ab4a79-7c36-4fc3-93b9-758bf5edbd00 | B6: 45969 | C6: 8 | D6: 1953.64
A7: 0518f99d-8e5b-496f-9c0b-34f0c24ee49f | B7: 45932 | C7: 6 | D7: 1068.08
A8: 060e33b3-e9ae-4899-a3d3-d742591d183b | B8: 46000 | C8: 9 | D8: 874.11
A9: 06ea8b50-0535-4c29-bc28-ff3c7c4ba7b8 | B9: 45844 | C9: 4 | D9: 547.76
A10: 08d68de0-766e-42e3-9145-4e030f805140 | B10: 45964 | C10: 3 | D10: 884.9
A11: 0a5d8031-b5a7-4be4-8d5d-63b70f2a67c7 | B11: 45845 | C11: 9 | D11: 1149.37
A12: 0aca39d0-c1c9-450c-bf56-9026ed1420ff | B12: 45873 | C12: 4 | D12: 392.22
A13: 0b59de48-4882-496e-98d7-a9053fe88877 | B13: 45756 | C13: 7 | D13: 1515.61
A14: 0dbeb864-49cc-4ff3-9ccc-3edec157aba2 | B14: 45843 | C14: 7 | D14: 2506.47
A15: 0e025dda-dcfd-4349-b45d-994ba4664cb3 | B15: 45970 | C15: 8 | D15: 943.09
... A183: Grand Total | B183: 46002 | C183: 1158 | D183: 235738.29

Sheet RFM Analysis
B1: Max Date | C1: =DATE(2025,12,15) -> 46006
A3: CustomerID | B3: Last Date of Purchase | C3: Recency | D3: Frequency | E3: Monetary | F3: R Score | G3: F Score | H3: M Score | I3: RFM Score | J3: RFM Segment
A4: 006bc8ad-8e59-4d6f-ab38-475a02a0f952 | B4: 45785 | C4: =DATEDIF(B4,$C$1,"d") -> 221 | D4: 8 | E4: 1248.55 | F4: =ROUND((1-_xlfn.PERCENTRANK.INC($C$4:$C$182,C4))*9,0) -> 1 | G4: =ROUND((1-_xlfn.PERCENTRANK.INC($D$4:$D$182,D4))*9,0) -> 3 | H4: =ROUND((1-_xlfn.PERCENTRANK.INC($E$4:$E$182,E4))*9,0) -> 4 | I4: =CONCATENATE(F4,G4,H4) -> 134 | J4: {=_xlfn.IFS(AND(F4>=8,G4>=8,H4>=8),"Champion",AND(F4>=6,G4>=7,H4>=6),"Loyal Customer",AND(F4>=6,G4>=5,H4>=5),"Potential Loyalist",AND(F4>=8,G4>=2,H4>=5),"New Customers",AND(F4>=6,G4>=2,H4>=3),"Promising",AND(F4>=3,G4>=3,H4>=3),"Need Attention",AND(F4>=4,G4>=6,H4>=6),"At Risk",AND(F4>=2,G4>=8,H4>=8),"Can't Lose Them",AND(F4>=2,G4>=2,H4>=2),"Hibernating",TRUE,"Other")} -> Other
A5: 019d6740-e346-47b9-b042-acab3646d400 | B5: 45843 | C5: =DATEDIF(B5,$C$1,"d") -> 163 | D5: 10 | E5: 825.56 | F5: =ROUND((1-_xlfn.PERCENTRANK.INC($C$4:$C$182,C5))*9,0) -> 2 | G5: =ROUND((1-_xlfn.PERCENTRANK.INC($D$4:$D$182,D5))*9,0) -> 0 | H5: =ROUND((1-_xlfn.PERCENTRANK.INC($E$4:$E$182,E5))*9,0) -> 6 | I5: =CONCATENATE(F5,G5,H5) -> 206 | J5: {=_xlfn.IFS(AND(F5>=8,G5>=8,H5>=8),"Champion",AND(F5>=6,G5>=7,H5>=6),"Loyal Customer",AND(F5>=6,G5>=5,H5>=5),"Potential Loyalist",AND(F5>=8,G5>=2,H5>=5),"New Customers",AND(F5>=6,G5>=2,H5>=3),"Promising",AND(F5>=3,G5>=3,H5>=3),"Need Attention",AND(F5>=4,G5>=6,H5>=6),"At Risk",AND(F5>=2,G5>=8,H5>=8),"Can't Lose Them",AND(F5>=2,G5>=2,H5>=2),"Hibernating",TRUE,"Other")} -> Other
A6: 01ab4a79-7c36-4fc3-93b9-758bf5edbd00 | B6: 45969 | C6: =DATEDIF(B6,$C$1,"d") -> 37 | D6: 8 | E6: 1953.64 | F6: =ROUND((1-_xlfn.PERCENTRANK.INC($C$4:$C$182,C6))*9,0) -> 7 | G6: =ROUND((1-_xlfn.PERCENTRANK.INC($D$4:$D$182,D6))*9,0) -> 3 | H6: =ROUND((1-_xlfn.PERCENTRANK.INC($E$4:$E$182,E6))*9,0) -> 2 | I6: =CONCATENATE(F6,G6,H6) -> 732 | J6: {=_xlfn.IFS(AND(F6>=8,G6>=8,H6>=8),"Champion",AND(F6>=6,G6>=7,H6>=6),"Loyal Customer",AND(F6>=6,G6>=5,H6>=5),"Potential Loyalist",AND(F6>=8,G6>=2,H6>=5),"New Customers",AND(F6>=6,G6>=2,H6>=3),"Promising",AND(F6>=3,G6>=3,H6>=3),"Need Attention",AND(F6>=4,G6>=6,H6>=6),"At Risk",AND(F6>=2,G6>=8,H6>=8),"Can't Lose Them",AND(F6>=2,G6>=2,H6>=2),"Hibernating",TRUE,"Other")} -> Hibernating
A7: 0518f99d-8e5b-496f-9c0b-34f0c24ee49f | B7: 45932 | C7: =DATEDIF(B7,$C$1,"d") -> 74 | D7: 6 | E7: 1068.08 | F7: =ROUND((1-_xlfn.PERCENTRANK.INC($C$4:$C$182,C7))*9,0) -> 5 | G7: =ROUND((1-_xlfn.PERCENTRANK.INC($D$4:$D$182,D7))*9,0) -> 6 | H7: =ROUND((1-_xlfn.PERCENTRANK.INC($E$4:$E$182,E7))*9,0) -> 5 | I7: =CONCATENATE(F7,G7,H7) -> 565 | J7: {=_xlfn.IFS(AND(F7>=8,G7>=8,H7>=8),"Champion",AND(F7>=6,G7>=7,H7>=6),"Loyal Customer",AND(F7>=6,G7>=5,H7>=5),"Potential Loyalist",AND(F7>=8,G7>=2,H7>=5),"New Customers",AND(F7>=6,G7>=2,H7>=3),"Promising",AND(F7>=3,G7>=3,H7>=3),"Need Attention",AND(F7>=4,G7>=6,H7>=6),"At Risk",AND(F7>=2,G7>=8,H7>=8),"Can't Lose Them",AND(F7>=2,G7>=2,H7>=2),"Hibernating",TRUE,"Other")} -> Need Attention
A8: 060e33b3-e9ae-4899-a3d3-d742591d183b | B8: 46000 | C8: =DATEDIF(B8,$C$1,"d") -> 6 | D8: 9 | E8: 874.11 | F8: =ROUND((1-_xlfn.PERCENTRANK.INC($C$4:$C$182,C8))*9,0) -> 9 | G8: =ROUND((1-_xlfn.PERCENTRANK.INC($D$4:$D$182,D8))*9,0) -> 2 | H8: =ROUND((1-_xlfn.PERCENTRANK.INC($E$4:$E$182,E8))*9,0) -> 6 | I8: =CONCATENATE(F8,G8,H8) -> 926 | J8: {=_xlfn.IFS(AND(F8>=8,G8>=8,H8>=8),"Champion",AND(F8>=6,G8>=7,H8>=6),"Loyal Customer",AND(F8>=6,G8>=5,H8>=5),"Potential Loyalist",AND(F8>=8,G8>=2,H8>=5),"New Customers",AND(F8>=6,G8>=2,H8>=3),"Promising",AND(F8>=3,G8>=3,H8>=3),"Need Attention",AND(F8>=4,G8>=6,H8>=6),"At Risk",AND(F8>=2,G8>=8,H8>=8),"Can't Lose Them",AND(F8>=2,G8>=2,H8>=2),"Hibernating",TRUE,"Other")} -> New Customers
A9: 06ea8b50-0535-4c29-bc28-ff3c7c4ba7b8 | B9: 45844 | C9: =DATEDIF(B9,$C$1,"d") -> 162 | D9: 4 | E9: 547.76 | F9: =ROUND((1-_xlfn.PERCENTRANK.INC($C$4:$C$182,C9))*9,0) -> 2 | G9: =ROUND((1-_xlfn.PERCENTRANK.INC($D$4:$D$182,D9))*9,0) -> 8 | H9: =ROUND((1-_xlfn.PERCENTRANK.INC($E$4:$E$182,E9))*9,0) -> 8 | I9: =CONCATENATE(F9,G9,H9) -> 288 | J9: {=_xlfn.IFS(AND(F9>=8,G9>=8,H9>=8),"Champion",AND(F9>=6,G9>=7,H9>=6),"Loyal Customer",AND(F9>=6,G9>=5,H9>=5),"Potential Loyalist",AND(F9>=8,G9>=2,H9>=5),"New Customers",AND(F9>=6,G9>=2,H9>=3),"Promising",AND(F9>=3,G9>=3,H9>=3),"Need Attention",AND(F9>=4,G9>=6,H9>=6),"At Risk",AND(F9>=2,G9>=8,H9>=8),"Can't Lose Them",AND(F9>=2,G9>=2,H9>=2),"Hibernating",TRUE,"Other")} -> Can't Lose Them
A10: 08d68de0-766e-42e3-9145-4e030f805140 | B10: 45964 | C10: =DATEDIF(B10,$C$1,"d") -> 42 | D10: 3 | E10: 884.9 | F10: =ROUND((1-_xlfn.PERCENTRANK.INC($C$4:$C$182,C10))*9,0) -> 6 | G10: =ROUND((1-_xlfn.PERCENTRANK.INC($D$4:$D$182,D10))*9,0) -> 9 | H10: =ROUND((1-_xlfn.PERCENTRANK.INC($E$4:$E$182,E10))*9,0) -> 6 | I10: =CONCATENATE(F10,G10,H10) -> 696 | J10: {=_xlfn.IFS(AND(F10>=8,G10>=8,H10>=8),"Champion",AND(F10>=6,G10>=7,H10>=6),"Loyal Customer",AND(F10>=6,G10>=5,H10>=5),"Potential Loyalist",AND(F10>=8,G10>=2,H10>=5),"New Customers",AND(F10>=6,G10>=2,H10>=3),"Promising",AND(F10>=3,G10>=3,H10>=3),"Need Attention",AND(F10>=4,G10>=6,H10>=6),"At Risk",AND(F10>=2,G10>=8,H10>=8),"Can't Lose Them",AND(F10>=2,G10>=2,H10>=2),"Hibernating",TRUE,"Other")} -> Loyal Customer
A11: 0a5d8031-b5a7-4be4-8d5d-63b70f2a67c7 | B11: 45845 | C11: =DATEDIF(B11,$C$1,"d") -> 161 | D11: 9 | E11: 1149.37 | F11: =ROUND((1-_xlfn.PERCENTRANK.INC($C$4:$C$182,C11))*9,0) -> 2 | G11: =ROUND((1-_xlfn.PERCENTRANK.INC($D$4:$D$182,D11))*9,0) -> 2 | H11: =ROUND((1-_xlfn.PERCENTRANK.INC($E$4:$E$182,E11))*9,0) -> 5 | I11: =CONCATENATE(F11,G11,H11) -> 225 | J11: {=_xlfn.IFS(AND(F11>=8,G11>=8,H11>=8),"Champion",AND(F11>=6,G11>=7,H11>=6),"Loyal Customer",AND(F11>=6,G11>=5,H11>=5),"Potential Loyalist",AND(F11>=8,G11>=2,H11>=5),"New Customers",AND(F11>=6,G11>=2,H11>=3),"Promising",AND(F11>=3,G11>=3,H11>=3),"Need Attention",AND(F11>=4,G11>=6,H11>=6),"At Risk",AND(F11>=2,G11>=8,H11>=8),"Can't Lose Them",AND(F11>=2,G11>=2,H11>=2),"Hibernating",TRUE,"Other")} -> Hibernating
A12: 0aca39d0-c1c9-450c-bf56-9026ed1420ff | B12: 45873 | C12: =DATEDIF(B12,$C$1,"d") -> 133 | D12: 4 | E12: 392.22 | F12: =ROUND((1-_xlfn.PERCENTRANK.INC($C$4:$C$182,C12))*9,0) -> 3 | G12: =ROUND((1-_xlfn.PERCENTRANK.INC($D$4:$D$182,D12))*9,0) -> 8 | H12: =ROUND((1-_xlfn.PERCENTRANK.INC($E$4:$E$182,E12))*9,0) -> 8 | I12: =CONCATENATE(F12,G12,H12) -> 388 | J12: {=_xlfn.IFS(AND(F12>=8,G12>=8,H12>=8),"Champion",AND(F12>=6,G12>=7,H12>=6),"Loyal Customer",AND(F12>=6,G12>=5,H12>=5),"Potential Loyalist",AND(F12>=8,G12>=2,H12>=5),"New Customers",AND(F12>=6,G12>=2,H12>=3),"Promising",AND(F12>=3,G12>=3,H12>=3),"Need Attention",AND(F12>=4,G12>=6,H12>=6),"At Risk",AND(F12>=2,G12>=8,H12>=8),"Can't Lose Them",AND(F12>=2,G12>=2,H12>=2),"Hibernating",TRUE,"Other")} -> Need Attention
A13: 0b59de48-4882-496e-98d7-a9053fe88877 | B13: 45756 | C13: =DATEDIF(B13,$C$1,"d") -> 250 | D13: 7 | E13: 1515.61 | F13: =ROUND((1-_xlfn.PERCENTRANK.INC($C$4:$C$182,C13))*9,0) -> 1 | G13: =ROUND((1-_xlfn.PERCENTRANK.INC($D$4:$D$182,D13))*9,0) -> 4 | H13: =ROUND((1-_xlfn.PERCENTRANK.INC($E$4:$E$182,E13))*9,0) -> 3 | I13: =CONCATENATE(F13,G13,H13) -> 143 | J13: {=_xlfn.IFS(AND(F13>=8,G13>=8,H13>=8),"Champion",AND(F13>=6,G13>=7,H13>=6),"Loyal Customer",AND(F13>=6,G13>=5,H13>=5),"Potential Loyalist",AND(F13>=8,G13>=2,H13>=5),"New Customers",AND(F13>=6,G13>=2,H13>=3),"Promising",AND(F13>=3,G13>=3,H13>=3),"Need Attention",AND(F13>=4,G13>=6,H13>=6),"At Risk",AND(F13>=2,G13>=8,H13>=8),"Can't Lose Them",AND(F13>=2,G13>=2,H13>=2),"Hibernating",TRUE,"Other")} -> Other
A14: 0dbeb864-49cc-4ff3-9ccc-3edec157aba2 | B14: 45843 | C14: =DATEDIF(B14,$C$1,"d") -> 163 | D14: 7 | E14: 2506.47 | F14: =ROUND((1-_xlfn.PERCENTRANK.INC($C$4:$C$182,C14))*9,0) -> 2 | G14: =ROUND((1-_xlfn.PERCENTRANK.INC($D$4:$D$182,D14))*9,0) -> 4 | H14: =ROUND((1-_xlfn.PERCENTRANK.INC($E$4:$E$182,E14))*9,0) -> 1 | I14: =CONCATENATE(F14,G14,H14) -> 241 | J14: {=_xlfn.IFS(AND(F14>=8,G14>=8,H14>=8),"Champion",AND(F14>=6,G14>=7,H14>=6),"Loyal Customer",AND(F14>=6,G14>=5,H14>=5),"Potential Loyalist",AND(F14>=8,G14>=2,H14>=5),"New Customers",AND(F14>=6,G14>=2,H14>=3),"Promising",AND(F14>=3,G14>=3,H14>=3),"Need Attention",AND(F14>=4,G14>=6,H14>=6),"At Risk",AND(F14>=2,G14>=8,H14>=8),"Can't Lose Them",AND(F14>=2,G14>=2,H14>=2),"Hibernating",TRUE,"Other")} -> Other
A15: 0e025dda-dcfd-4349-b45d-994ba4664cb3 | B15: 45970 | C15: =DATEDIF(B15,$C$1,"d") -> 36 | D15: 8 | E15: 943.09 | F15: =ROUND((1-_xlfn.PERCENTRANK.INC($C$4:$C$182,C15))*9,0) -> 7 | G15: =ROUND((1-_xlfn.PERCENTRANK.INC($D$4:$D$182,D15))*9,0) -> 3 | H15: =ROUND((1-_xlfn.PERCENTRANK.INC($E$4:$E$182,E15))*9,0) -> 6 | I15: =CONCATENATE(F15,G15,H15) -> 736 | J15: {=_xlfn.IFS(AND(F15>=8,G15>=8,H15>=8),"Champion",AND(F15>=6,G15>=7,H15>=6),"Loyal Customer",AND(F15>=6,G15>=5,H15>=5),"Potential Loyalist",AND(F15>=8,G15>=2,H15>=5),"New Customers",AND(F15>=6,G15>=2,H15>=3),"Promising",AND(F15>=3,G15>=3,H15>=3),"Need Attention",AND(F15>=4,G15>=6,H15>=6),"At Risk",AND(F15>=2,G15>=8,H15>=8),"Can't Lose Them",AND(F15>=2,G15>=2,H15>=2),"Hibernating",TRUE,"Other")} -> Promising
... A182: ff2be8d4-a06b-4c87-aefa-1f4020ebc0e2 | B182: 45814 | C182: =DATEDIF(B182,$C$1,"d") -> 192 | D182: 9 | E182: 2266.37 | F182: =ROUND((1-_xlfn.PERCENTRANK.INC($C$4:$C$182,C182))*9,0) -> 2 | G182: =ROUND((1-_xlfn.PERCENTRANK.INC($D$4:$D$182,D182))*9,0) -> 2 | H182: =ROUND((1-_xlfn.PERCENTRANK.INC($E$4:$E$182,E182))*9,0) -> 1 | I182: =CONCATENATE(F182,G182,H182) -> 221 | J182: {=_xlfn.IFS(AND(F182>=8,G182>=8,H182>=8),"Champion",AND(F182>=6,G182>=7,H182>=6),"Loyal Customer",AND(F182>=6,G182>=5,H182>=5),"Potential Loyalist",AND(F182>=8,G182>=2,H182>=5),"New Customers",AND(F182>=6,G182>=2,H182>=3),"Promising",AND(F182>=3,G182>=3,H182>=3),"Need Attention",AND(F182>=4,G182>=6,H182>=6),"At Risk",AND(F182>=2,G182>=8,H182>=8),"Can't Lose Them",AND(F182>=2,G182>=2,H182>=2),"Hibernating",TRUE,"Other")} -> Other

Sheet Customer Segmentation
A12: Segment | B12: Customer Count
A13: Other | B13: =COUNTIFS('RFM Analysis'!J3:$J$182,A13) -> 63
A14: Need Attention | B14: =COUNTIFS('RFM Analysis'!J4:$J$182,A14) -> 32
A15: Hibernating | B15: =COUNTIFS('RFM Analysis'!J5:$J$182,A15) -> 30
A16: Promising | B16: =COUNTIFS('RFM Analysis'!J6:$J$182,A16) -> 18
A17: Loyal Customer | B17: =COUNTIFS('RFM Analysis'!J7:$J$182,A17) -> 13
A18: Potential Loyalist | B18: =COUNTIFS('RFM Analysis'!J8:$J$182,A18) -> 11
A19: New Customers | B19: =COUNTIFS('RFM Analysis'!J9:$J$182,A19) -> 6
A20: Champion | B20: =COUNTIFS('RFM Analysis'!J10:$J$182,A20) -> 3
A21: At Risk | B21: =COUNTIFS('RFM Analysis'!J11:$J$182,A21) -> 0
A22: Segments | B22: Definition Of Segments | C22: Strategy
A23: Cant lose them | B23: Former regular customers who have stopped buying | C23: Offer exclusive reactivation campaigns and get feedback
A24: Champion | B24: Your best customers who recently purchased, buy | C24: Give exclusive offers and early access to new products
B25: frequently and spend the most
A26: Hibernating | B26: Haven't purchased in a long time and were once active | C26: Offer small, target promotions to wake them up without
C27: significant expenditure
A28: Loyal | B28: They are frequent purchasers | C28: Offer loyalty programs, complementary products and
C29: encourage higher spending through bundle deals.
A30: Need attention | B30: Haven't bought for a long time and are not big spenders | C30: Win them back with re-engagement campaigns or deals
A31: New Customer | B31: Just made their first or early purchase | C31: Build trust by post-purchase communication and offer
C32: discount for second purchase
A33: Potential loyalists | B33: Recent customers with average frequency but good | C33: Send follow-up offers, welcome series emails and value
B34: spending | C34: propositions
A35: Promising | B35: Recent customers who have potential but haven't | C35: Focus on building loyalty and encouraging repeat purchase
B36: bought much yet
A37: At Risk | B37: Customers who purchase frequently and are big | C37: Use win back campaigns with strong incentives, share informative
B38: spenders but haven't made a purchase recently | C38: and entertaining content via social media platforms
